Workbook

Sheet Mon-Sun comparison
A1: Day | B1: Hour | C1: 150rep page (0-100) | D1: Page level | E1: Google Popular Times (est.) | F1: Google label | G1: Difference (Google - page) | I1: Legend and settings
A2: Monday | B2: 6 AM | C2: 22 | D2: =IF(C2<$K$11,"Quiet",IF(C2<$K$12,"Moderate","Packed")) -> Quiet | F2: =IF(E2="","",IF(E2>=$K$10,"Busy",IF(E2>=$K$9,"A little busy","Not too busy"))) | G2: =IF(E2="","",E2-C2) | I2: Yellow cells (column E) are for Google Popular Times values; only Saturday is filled in so far.
A3: Monday | B3: 7 AM | C3: 32 | D3: =IF(C3<$K$11,"Quiet",IF(C3<$K$12,"Moderate","Packed")) -> Quiet | F3: =IF(E3="","",IF(E3>=$K$10,"Busy",IF(E3>=$K$9,"A little busy","Not too busy"))) | G3: =IF(E3="","",E3-C3) | I3: Google values are estimated by eye from a screenshot (tallest bar = 100), so they are approximate.
A4: Monday | B4: 8 AM | C4: 34 | D4: =IF(C4<$K$11,"Quiet",IF(C4<$K$12,"Moderate","Packed")) -> Moderate | F4: =IF(E4="","",IF(E4>=$K$10,"Busy",IF(E4>=$K$9,"A little busy","Not too busy"))) | G4: =IF(E4="","",E4-C4) | I4: Page values come from the 150rep landing page's busy-hours data, labeled illustrative. Page level thresholds match the page's code (34 and 67).
A5: Monday | B5: 9 AM | C5: 32 | D5: =IF(C5<$K$11,"Quiet",IF(C5<$K$12,"Moderate","Packed")) -> Quiet | F5: =IF(E5="","",IF(E5>=$K$10,"Busy",IF(E5>=$K$9,"A little busy","Not too busy"))) | G5: =IF(E5="","",E5-C5) | I5: Google label is my approximation: Google's graph has no numbers, so the cutoffs below are assumptions you can edit.
A6: Monday | B6: 10 AM | C6: 34 | D6: =IF(C6<$K$11,"Quiet",IF(C6<$K$12,"Moderate","Packed")) -> Moderate | F6: =IF(E6="","",IF(E6>=$K$10,"Busy",IF(E6>=$K$9,"A little busy","Not too busy"))) | G6: =IF(E6="","",E6-C6) | I6: Only 'A little busy' is confirmed (Saturday 2 PM live reading). 'Busy' needs screenshots from busier days to calibrate.
A7: Monday | B7: 11 AM | C7: 38 | D7: =IF(C7<$K$11,"Quiet",IF(C7<$K$12,"Moderate","Packed")) -> Moderate | F7: =IF(E7="","",IF(E7>=$K$10,"Busy",IF(E7>=$K$9,"A little busy","Not too busy"))) | G7: =IF(E7="","",E7-C7)
A8: Monday | B8: 12 PM | C8: 42 | D8: =IF(C8<$K$11,"Quiet",IF(C8<$K$12,"Moderate","Packed")) -> Moderate | F8: =IF(E8="","",IF(E8>=$K$10,"Busy",IF(E8>=$K$9,"A little busy","Not too busy"))) | G8: =IF(E8="","",E8-C8)
A9: Monday | B9: 1 PM | C9: 38 | D9: =IF(C9<$K$11,"Quiet",IF(C9<$K$12,"Moderate","Packed")) -> Moderate | F9: =IF(E9="","",IF(E9>=$K$10,"Busy",IF(E9>=$K$9,"A little busy","Not too busy"))) | G9: =IF(E9="","",E9-C9) | I9: 'A little busy' starts at | K9: 40
A10: Monday | B10: 2 PM | C10: 38 | D10: =IF(C10<$K$11,"Quiet",IF(C10<$K$12,"Moderate","Packed")) -> Moderate | F10: =IF(E10="","",IF(E10>=$K$10,"Busy",IF(E10>=$K$9,"A little busy","Not too busy"))) | G10: =IF(E10="","",E10-C10) | I10: 'Busy' starts at | K10: 101
A11: Monday | B11: 3 PM | C11: 46 | D11: =IF(C11<$K$11,"Quiet",IF(C11<$K$12,"Moderate","Packed")) -> Moderate | F11: =IF(E11="","",IF(E11>=$K$10,"Busy",IF(E11>=$K$9,"A little busy","Not too busy"))) | G11: =IF(E11="","",E11-C11) | I11: Page 'Moderate' starts at | K11: 34
A12: Monday | B12: 4 PM | C12: 64 | D12: =IF(C12<$K$11,"Quiet",IF(C12<$K$12,"Moderate","Packed")) -> Moderate | F12: =IF(E12="","",IF(E12>=$K$10,"Busy",IF(E12>=$K$9,"A little busy","Not too busy"))) | G12: =IF(E12="","",E12-C12) | I12: Page 'Packed' starts at | K12: 67
A13: Monday | B13: 5 PM | C13: 88 | D13: =IF(C13<$K$11,"Quiet",IF(C13<$K$12,"Moderate","Packed")) -> Packed | F13: =IF(E13="","",IF(E13>=$K$10,"Busy",IF(E13>=$K$9,"A little busy","Not too busy"))) | G13: =IF(E13="","",E13-C13) | I13: Average gap (days entered) | K13: =IFERROR(AVERAGE(G2:G127),"") -> 50.375
A14: Monday | B14: 6 PM | C14: 99 | D14: =IF(C14<$K$11,"Quiet",IF(C14<$K$12,"Moderate","Packed")) -> Packed | F14: =IF(E14="","",IF(E14>=$K$10,"Busy",IF(E14>=$K$9,"A little busy","Not too busy"))) | G14: =IF(E14="","",E14-C14)
A15: Monday | B15: 7 PM | C15: 100 | D15: =IF(C15<$K$11,"Quiet",IF(C15<$K$12,"Moderate","Packed")) -> Packed | F15: =IF(E15="","",IF(E15>=$K$10,"Busy",IF(E15>=$K$9,"A little busy","Not too busy"))) | G15: =IF(E15="","",E15-C15)
A16: Monday | B16: 8 PM | C16: 86 | D16: =IF(C16<$K$11,"Quiet",IF(C16<$K$12,"Moderate","Packed")) -> Packed | F16: =IF(E16="","",IF(E16>=$K$10,"Busy",IF(E16>=$K$9,"A little busy","Not too busy"))) | G16: =IF(E16="","",E16-C16)
A17: Monday | B17: 9 PM | C17: 60 | D17: =IF(C17<$K$11,"Quiet",IF(C17<$K$12,"Moderate","Packed")) -> Moderate | F17: =IF(E17="","",IF(E17>=$K$10,"Busy",IF(E17>=$K$9,"A little busy","Not too busy"))) | G17: =IF(E17="","",E17-C17)
A18: Monday | B18: 10 PM | C18: 34 | D18: =IF(C18<$K$11,"Quiet",IF(C18<$K$12,"Moderate","Packed")) -> Moderate | F18: =IF(E18="","",IF(E18>=$K$10,"Busy",IF(E18>=$K$9,"A little busy","Not too busy"))) | G18: =IF(E18="","",E18-C18)
A19: Monday | B19: 11 PM | C19: 17 | D19: =IF(C19<$K$11,"Quiet",IF(C19<$K$12,"Moderate","Packed")) -> Quiet | F19: =IF(E19="","",IF(E19>=$K$10,"Busy",IF(E19>=$K$9,"A little busy","Not too busy"))) | G19: =IF(E19="","",E19-C19)
A20: Tuesday | B20: 6 AM | C20: 32 | D20: =IF(C20<$K$11,"Quiet",IF(C20<$K$12,"Moderate","Packed")) -> Quiet | F20: =IF(E20="","",IF(E20>=$K$10,"Busy",IF(E20>=$K$9,"A little busy","Not too busy"))) | G20: =IF(E20="","",E20-C20)
A21: Tuesday | B21: 7 AM | C21: 40 | D21: =IF(C21<$K$11,"Quiet",IF(C21<$K$12,"Moderate","Packed")) -> Moderate | F21: =IF(E21="","",IF(E21>=$K$10,"Busy",IF(E21>=$K$9,"A little busy","Not too busy"))) | G21: =IF(E21="","",E21-C21)
A22: Tuesday | B22: 8 AM | C22: 34 | D22: =IF(C22<$K$11,"Quiet",IF(C22<$K$12,"Moderate","Packed")) -> Moderate | F22: =IF(E22="","",IF(E22>=$K$10,"Busy",IF(E22>=$K$9,"A little busy","Not too busy"))) | G22: =IF(E22="","",E22-C22)
A23: Tuesday | B23: 9 AM | C23: 32 | D23: =IF(C23<$K$11,"Quiet",IF(C23<$K$12,"Moderate","Packed")) -> Quiet | F23: =IF(E23="","",IF(E23>=$K$10,"Busy",IF(E23>=$K$9,"A little busy","Not too busy"))) | G23: =IF(E23="","",E23-C23)
A24: Tuesday | B24: 10 AM | C24: 42 | D24: =IF(C24<$K$11,"Quiet",IF(C24<$K$12,"Moderate","Packed")) -> Moderate | F24: =IF(E24="","",IF(E24>=$K$10,"Busy",IF(E24>=$K$9,"A little busy","Not too busy"))) | G24: =IF(E24="","",E24-C24)
A25: Tuesday | B25: 11 AM | C25: 55 | D25: =IF(C25<$K$11,"Quiet",IF(C25<$K$12,"Moderate","Packed")) -> Moderate | F25: =IF(E25="","",IF(E25>=$K$10,"Busy",IF(E25>=$K$9,"A little busy","Not too busy"))) | G25: =IF(E25="","",E25-C25)
... A93: Saturday | B93: 7 AM | C93: 12 | D93: =IF(C93<$K$11,"Quiet",IF(C93<$K$12,"Moderate","Packed")) -> Quiet | F93: =IF(E93="","",IF(E93>=$K$10,"Busy",IF(E93>=$K$9,"A little busy","Not too busy"))) | G93: =IF(E93="","",E93-C93)
A94: Saturday | B94: 8 AM | C94: 22 | D94: =IF(C94<$K$11,"Quiet",IF(C94<$K$12,"Moderate","Packed")) -> Quiet | E94: 50 | F94: =IF(E94="","",IF(E94>=$K$10,"Busy",IF(E94>=$K$9,"A little busy","Not too busy"))) -> A little busy | G94: =IF(E94="","",E94-C94) -> 28
A95: Saturday | B95: 9 AM | C95: 38 | D95: =IF(C95<$K$11,"Quiet",IF(C95<$K$12,"Moderate","Packed")) -> Moderate | F95: =IF(E95="","",IF(E95>=$K$10,"Busy",IF(E95>=$K$9,"A little busy","Not too busy"))) | G95: =IF(E95="","",E95-C95)
A96: Saturday | B96: 10 AM | C96: 50 | D96: =IF(C96<$K$11,"Quiet",IF(C96<$K$12,"Moderate","Packed")) -> Moderate | E96: 85 | F96: =IF(E96="","",IF(E96>=$K$10,"Busy",IF(E96>=$K$9,"A little busy","Not too busy"))) -> A little busy | G96: =IF(E96="","",E96-C96) -> 35
A97: Saturday | B97: 11 AM | C97: 55 | D97: =IF(C97<$K$11,"Quiet",IF(C97<$K$12,"Moderate","Packed")) -> Moderate | F97: =IF(E97="","",IF(E97>=$K$10,"Busy",IF(E97>=$K$9,"A little busy","Not too busy"))) | G97: =IF(E97="","",E97-C97)
A98: Saturday | B98: 12 PM | C98: 52 | D98: =IF(C98<$K$11,"Quiet",IF(C98<$K$12,"Moderate","Packed")) -> Moderate | E98: 78 | F98: =IF(E98="","",IF(E98>=$K$10,"Busy",IF(E98>=$K$9,"A little busy","Not too busy"))) -> A little busy | G98: =IF(E98="","",E98-C98) -> 26
A99: Saturday | B99: 1 PM | C99: 45 | D99: =IF(C99<$K$11,"Quiet",IF(C99<$K$12,"Moderate","Packed")) -> Moderate | F99: =IF(E99="","",IF(E99>=$K$10,"Busy",IF(E99>=$K$9,"A little busy","Not too busy"))) | G99: =IF(E99="","",E99-C99)
A100: Saturday | B100: 2 PM | C100: 40 | D100: =IF(C100<$K$11,"Quiet",IF(C100<$K$12,"Moderate","Packed")) -> Moderate | E100: 97 | F100: =IF(E100="","",IF(E100>=$K$10,"Busy",IF(E100>=$K$9,"A little busy","Not too busy"))) -> A little busy | G100: =IF(E100="","",E100-C100) -> 57
A101: Saturday | B101: 3 PM | C101: 35 | D101: =IF(C101<$K$11,"Quiet",IF(C101<$K$12,"Moderate","Packed")) -> Moderate | F101: =IF(E101="","",IF(E101>=$K$10,"Busy",IF(E101>=$K$9,"A little busy","Not too busy"))) | G101: =IF(E101="","",E101-C101)
A102: Saturday | B102: 4 PM | C102: 30 | D102: =IF(C102<$K$11,"Quiet",IF(C102<$K$12,"Moderate","Packed")) -> Quiet | E102: 88 | F102: =IF(E102="","",IF(E102>=$K$10,"Busy",IF(E102>=$K$9,"A little busy","Not too busy"))) -> A little busy | G102: =IF(E102="","",E102-C102) -> 58
A103: Saturday | B103: 5 PM | C103: 24 | D103: =IF(C103<$K$11,"Quiet",IF(C103<$K$12,"Moderate","Packed")) -> Quiet | E103: 100 | F103: =IF(E103="","",IF(E103>=$K$10,"Busy",IF(E103>=$K$9,"A little busy","Not too busy"))) -> A little busy | G103: =IF(E103="","",E103-C103) -> 76
A104: Saturday | B104: 6 PM | C104: 18 | D104: =IF(C104<$K$11,"Quiet",IF(C104<$K$12,"Moderate","Packed")) -> Quiet | E104: 99 | F104: =IF(E104="","",IF(E104>=$K$10,"Busy",IF(E104>=$K$9,"A little busy","Not too busy"))) -> A little busy | G104: =IF(E104="","",E104-C104) -> 81
A105: Saturday | B105: 7 PM | C105: 12 | D105: =IF(C105<$K$11,"Quiet",IF(C105<$K$12,"Moderate","Packed")) -> Quiet | F105: =IF(E105="","",IF(E105>=$K$10,"Busy",IF(E105>=$K$9,"A little busy","Not too busy"))) | G105: =IF(E105="","",E105-C105)
A106: Saturday | B106: 8 PM | C106: 8 | D106: =IF(C106<$K$11,"Quiet",IF(C106<$K$12,"Moderate","Packed")) -> Quiet | E106: 50 | F106: =IF(E106="","",IF(E106>=$K$10,"Busy",IF(E106>=$K$9,"A little busy","Not too busy"))) -> A little busy | G106: =IF(E106="","",E106-C106) -> 42
A107: Saturday | B107: 9 PM | C107: 5 | D107: =IF(C107<$K$11,"Quiet",IF(C107<$K$12,"Moderate","Packed")) -> Quiet | F107: =IF(E107="","",IF(E107>=$K$10,"Busy",IF(E107>=$K$9,"A little busy","Not too busy"))) | G107: =IF(E107="","",E107-C107)
...

Sheet Saturday comparison
A1: Hour | B1: Google Popular Times (est.) | C1: Google label | D1: 150rep page (Saturday, 0-100) | E1: Page level | F1: Difference (Google - page) | G1: Note
A2: 8 AM | B2: 50 | C2: =IF(B2>='Mon-Sun comparison'!$K$10,"Busy",IF(B2>='Mon-Sun comparison'!$K$9,"A little busy","Not too busy")) -> A little busy | D2: 22 | E2: =IF(D2<'Mon-Sun comparison'!$K$11,"Quiet",IF(D2<'Mon-Sun comparison'!$K$12,"Moderate","Packed")) -> Quiet | F2: =B2-D2 -> 28
A3: 10 AM | B3: 85 | C3: =IF(B3>='Mon-Sun comparison'!$K$10,"Busy",IF(B3>='Mon-Sun comparison'!$K$9,"A little busy","Not too busy")) -> A little busy | D3: 50 | E3: =IF(D3<'Mon-Sun comparison'!$K$11,"Quiet",IF(D3<'Mon-Sun comparison'!$K$12,"Moderate","Packed")) -> Moderate | F3: =B3-D3 -> 35
A4: 12 PM | B4: 78 | C4: =IF(B4>='Mon-Sun comparison'!$K$10,"Busy",IF(B4>='Mon-Sun comparison'!$K$9,"A little busy","Not too busy")) -> A little busy | D4: 52 | E4: =IF(D4<'Mon-Sun comparison'!$K$11,"Quiet",IF(D4<'Mon-Sun comparison'!$K$12,"Moderate","Packed")) -> Moderate | F4: =B4-D4 -> 26
A5: 2 PM | B5: 97 | C5: =IF(B5>='Mon-Sun comparison'!$K$10,"Busy",IF(B5>='Mon-Sun comparison'!$K$9,"A little busy","Not too busy")) -> A little busy | D5: 40 | E5: =IF(D5<'Mon-Sun comparison'!$K$11,"Quiet",IF(D5<'Mon-Sun comparison'!$K$12,"Moderate","Packed")) -> Moderate | F5: =B5-D5 -> 57 | G5: Google live reading: 'A little busy'
A6: 4 PM | B6: 88 | C6: =IF(B6>='Mon-Sun comparison'!$K$10,"Busy",IF(B6>='Mon-Sun comparison'!$K$9,"A little busy","Not too busy")) -> A little busy | D6: 30 | E6: =IF(D6<'Mon-Sun comparison'!$K$11,"Quiet",IF(D6<'Mon-Sun comparison'!$K$12,"Moderate","Packed")) -> Quiet | F6: =B6-D6 -> 58
A7: 5 PM | B7: 100 | C7: =IF(B7>='Mon-Sun comparison'!$K$10,"Busy",IF(B7>='Mon-Sun comparison'!$K$9,"A little busy","Not too busy")) -> A little busy | D7: 24 | E7: =IF(D7<'Mon-Sun comparison'!$K$11,"Quiet",IF(D7<'Mon-Sun comparison'!$K$12,"Moderate","Packed")) -> Quiet | F7: =B7-D7 -> 76 | G7: Google peak
A8: 6 PM | B8: 99 | C8: =IF(B8>='Mon-Sun comparison'!$K$10,"Busy",IF(B8>='Mon-Sun comparison'!$K$9,"A little busy","Not too busy")) -> A little busy | D8: 18 | E8: =IF(D8<'Mon-Sun comparison'!$K$11,"Quiet",IF(D8<'Mon-Sun comparison'!$K$12,"Moderate","Packed")) -> Quiet | F8: =B8-D8 -> 81
A9: 8 PM | B9: 50 | C9: =IF(B9>='Mon-Sun comparison'!$K$10,"Busy",IF(B9>='Mon-Sun comparison'!$K$9,"A little busy","Not too busy")) -> A little busy | D9: 8 | E9: =IF(D9<'Mon-Sun comparison'!$K$11,"Quiet",IF(D9<'Mon-Sun comparison'!$K$12,"Moderate","Packed")) -> Quiet | F9: =B9-D9 -> 42
A11: Average gap | F11: =AVERAGE(F2:F9) -> 50.375
A13: Notes
A14: Google values estimated by eye from a screenshot; tallest bar = 100. Neither series is a headcount.
A15: Labels use the editable cutoffs on the Mon-Sun comparison sheet.

Sheet Page grid
A1: Hour | B1: Monday | C1: Tuesday | D1: Wednesday | E1: Thursday | F1: Friday | G1: Saturday | H1: Sunday
A2: 6 AM | B2: 22 | C2: 32 | D2: 28 | E2: 31 | F2: 26 | G2: 8 | H2: 6
A3: 7 AM | B3: 32 | C3: 40 | D3: 36 | E3: 39 | F3: 34 | G3: 12 | H3: 10
A4: 8 AM | B4: 34 | C4: 34 | D4: 30 | E4: 33 | F4: 30 | G4: 22 | H4: 18
A5: 9 AM | B5: 32 | C5: 32 | D5: 28 | E5: 31 | F5: 32 | G5: 38 | H5: 30
A6: 10 AM | B6: 34 | C6: 42 | D6: 38 | E6: 41 | F6: 40 | G6: 50 | H6: 42
A7: 11 AM | B7: 38 | C7: 55 | D7: 50 | E7: 54 | F7: 48 | G7: 55 | H7: 50
A8: 12 PM | B8: 42 | C8: 52 | D8: 48 | E8: 51 | F8: 46 | G8: 52 | H8: 54
A9: 1 PM | B9: 38 | C9: 40 | D9: 36 | E9: 39 | F9: 36 | G9: 45 | H9: 48
A10: 2 PM | B10: 38 | C10: 36 | D10: 32 | E10: 35 | F10: 30 | G10: 40 | H10: 42
A11: 3 PM | B11: 46 | C11: 50 | D11: 46 | E11: 49 | F11: 40 | G11: 35 | H11: 38
A12: 4 PM | B12: 64 | C12: 70 | D12: 66 | E12: 69 | F12: 54 | G12: 30 | H12: 36
A13: 5 PM | B13: 88 | C13: 88 | D13: 82 | E13: 86 | F13: 66 | G13: 24 | H13: 34
... A19: 11 PM | B19: 17 | C19: 12 | D19: 10 | E19: 11 | F19: 8 | G19: 2 | H19: 3
